<?xml version="1.0" encoding="utf-8"?>
<robot name="toydog" xmlns:xacro="http://www.ros.org/wiki/xacro">

<material name="blue">	
    <color rgba="0 0 0.8 1"/>
  </material>
  <material name="black">
    <color rgba="0 0 0 1"/>
  </material>
  <material name="white">
    <color rgba="1 1 1 1"/>
  </material>       


  <link name = "base_link">
   <visual>
    <geometry>
     <box size="0.6 0.3 0.1" />
    </geometry>

     <material name = "blue"/>
     <origin rpy="0 0 0" xyz="0 0 0.5"/>
    </visual>

    <collision>
     <origin rpy="0 0 0" xyz="0 0 0.5"/>
    <geometry>
     <box size="0.6 0.3 0.1" />
    </geometry>
    </collision>

    <inertial>
     <origin rpy="0 0 0" xyz="0 0 0.5"/>
      <mass value="0.03" />
      <inertia ixx="1.0" ixy="0.0" ixz="0.0"
                         iyy="1.0" iyz="0.0"
                                   izz="1.0" />
  </inertial>
   </link> 

<!--first leg-->
  <link name = "fore_leg_right">
   <visual>
     <material name = "white"/>
     <origin rpy="0 0 0" xyz="0 0 -0.15"/>
    <geometry>
     <box size="0.1 0.1 0.3" />
    </geometry>
    </visual>

    <collision>
     <origin rpy="0 0 0" xyz="0 0 -0.15"/>
    <geometry>
     <box size="0.1 0.1 0.3" />
    </geometry>
    </collision>

    <inertial>
     <origin rpy="0 0 0" xyz="0 0 -0.15"/>
      <mass value="0.03" />
      <inertia ixx="1.0" ixy="0.0" ixz="0.0"
                         iyy="1.0" iyz="0.0"
                                   izz="1.0" />
  </inertial>
   </link> 


  <joint name="joint1" type="revolute">
    <parent link="base_link"/>
    <child link="fore_leg_right"/>
    <origin xyz="0.2 0.2 0.5"/>
    <axis xyz="0 1 0"/>
    <limit lower="-1.57" upper="1.57" effort="0.5293" velocity="6.159937255" />
  </joint>
 <transmission name="trans1">
    <type>transmission_interface/SimpleTransmission</type>
    <joint name="joint1"> 
      <hardwareInterface>hardware_interface/EffortJointInterface</hardwareInterface>
    </joint>
    <actuator name="motor1">
       <hardwareInterface>hardware_interface/EffortJointInterface</hardwareInterface>
       <mechanismReduction>1</mechanismReduction>
    </actuator>
 </transmission>


  <link name = "fore_leg_right2">
   <visual>
    <geometry>
     <box size="0.15 0.1 0.1" />
    </geometry>
     <material name = "white"/>
     <origin rpy="0 0 0" xyz="0.05 0 -0.05"/>
    </visual>

    <collision>
     <origin rpy="0 0 0" xyz="0.05 0 -0.05"/>
    <geometry>
     <box size="0.15 0.1 0.1" />
    </geometry>
    </collision>

    <inertial>
     <origin rpy="0 0 0" xyz="0.05 0 -0.05"/>
      <mass value="0.03" />
      <inertia ixx="1.0" ixy="0.0" ixz="0.0"
                         iyy="1.0" iyz="0.0"
                                   izz="1.0" />
  </inertial>
   </link> 

  <joint name="joint2" type="revolute">
    <parent link="fore_leg_right"/>
    <child link="fore_leg_right2"/>
    <origin xyz="0 0 -0.3"/>
    <axis xyz="0 1 0"/>
    <limit lower="-0.3" upper="1.57" effort="0.5293" velocity="6.159937255" />
  </joint>
 <transmission name="trans2">
    <type>transmission_interface/SimpleTransmission</type>
    <joint name="joint2"> 
      <hardwareInterface>hardware_interface/EffortJointInterface</hardwareInterface>
    </joint>
    <actuator name="motor2">
       <hardwareInterface>hardware_interface/EffortJointInterface</hardwareInterface>
       <mechanismReduction>1</mechanismReduction>
    </actuator>
 </transmission>

<!--second leg-->  
  <link name = "fore_leg_left">
   <visual>
    <geometry>
     <box size="0.1 0.1 0.3" />
    </geometry>
     <material name = "white"/>
     <origin rpy="0 0 0" xyz="0 0 -0.15"/>
    </visual>

    <collision>
     <origin rpy="0 0 0" xyz="0 0 -0.15"/>
     <geometry>
     <box size="0.1 0.1 0.3" />
     </geometry>
    </collision>

    <inertial>
     <origin rpy="0 0 0" xyz="0 0 -0.15"/>
      <mass value="0.03" />
      <inertia ixx="1.0" ixy="0.0" ixz="0.0"
                         iyy="1.0" iyz="0.0"
                                   izz="1.0" />
  </inertial>
   </link> 


  <joint name="joint3" type="revolute">
    <parent link="base_link"/>
    <child link="fore_leg_left"/>
    <origin rpy="0 0 0 " xyz="0.2 -0.2 0.5"/>
    <axis xyz="0 1 0"/>
    <limit lower="-1.57" upper="1.57" effort="0.5293" velocity="6.159937255" />
  </joint>
 <transmission name="trans3">
    <type>transmission_interface/SimpleTransmission</type>
    <joint name="joint3"> 
      <hardwareInterface>hardware_interface/EffortJointInterface</hardwareInterface>
    </joint>
    <actuator name="motor3">
       <hardwareInterface>hardware_interface/EffortJointInterface</hardwareInterface>
       <mechanismReduction>1</mechanismReduction>
    </actuator>
 </transmission>



  <link name = "fore_leg_left2">
   <visual>
    <geometry>
     <box size="0.15 0.1 0.1" />
    </geometry>
     <material name = "white"/>
     <origin rpy="0 0 0" xyz="0.05 0 -0.05"/>
    </visual>

    <collision>
     <origin rpy="0 0 0" xyz="0.05 0 -0.05"/>
     <geometry>
     <box size="0.15 0.1 0.1" />
     </geometry>
    </collision>

    <inertial>
     <origin rpy="0 0 0" xyz="0.05 0 -0.05"/>
      <mass value="0.03" />
      <inertia ixx="1.0" ixy="0.0" ixz="0.0"
                         iyy="1.0" iyz="0.0"
                                   izz="1.0" />
  </inertial>
   </link> 

  <joint name="joint4" type="revolute">
    <parent link="fore_leg_left"/>
    <child link="fore_leg_left2"/>
    <origin xyz="0 0 -0.3"/>
    <axis xyz="0 1 0"/>
    <limit lower="-0.3" upper="1.57" effort="0.5293" velocity="6.159937255" />
  </joint>
 <transmission name="trans4">
    <type>transmission_interface/SimpleTransmission</type>
    <joint name="joint4"> 
      <hardwareInterface>hardware_interface/EffortJointInterface</hardwareInterface>
    </joint>
    <actuator name="motor4">
       <hardwareInterface>hardware_interface/EffortJointInterface</hardwareInterface>
       <mechanismReduction>1</mechanismReduction>
    </actuator>
 </transmission>

<!--third leg-->  
  <link name = "hind_leg_right">
   <visual>
    <geometry>
     <box size="0.1 0.1 0.3" />
    </geometry>
     <material name = "white"/>
     <origin rpy="0 0 0" xyz="0 0 -0.15"/>
    </visual>

    <collision>
     <origin rpy="0 0 0" xyz="0 0 -0.15"/>
     <geometry>
     <box size="0.1 0.1 0.3" />
     </geometry>
    </collision>

    <inertial>
     <origin rpy="0 0 0" xyz="0 0 -0.15"/>
      <mass value="0.03" />
      <inertia ixx="1.0" ixy="0.0" ixz="0.0"
                         iyy="1.0" iyz="0.0"
                                   izz="1.0" />
  </inertial>
   </link> 


  <joint name="joint5" type="revolute">
    <parent link="base_link"/>
    <child link="hind_leg_right"/>
    <origin xyz="-0.2 0.2 0.5"/>
    <axis xyz="0 1 0"/>
    <limit lower="-1.57" upper="1.57" effort="0.5293" velocity="6.159937255" />
  </joint>
 <transmission name="trans5">
    <type>transmission_interface/SimpleTransmission</type>
    <joint name="joint5"> 
      <hardwareInterface>hardware_interface/EffortJointInterface</hardwareInterface>
    </joint>
    <actuator name="motor5">
       <hardwareInterface>hardware_interface/EffortJointInterface</hardwareInterface>
       <mechanismReduction>1</mechanismReduction>
    </actuator>
 </transmission>



  <link name = "hind_leg_right2">
   <visual>
    <geometry>
     <box size="0.15 0.1 0.1" />
    </geometry>
     <material name = "white"/>
     <origin rpy="0 0 0" xyz="0.05 0 -0.05"/>
    </visual>

    <collision>
     <origin rpy="0 0 0" xyz="0.05 0 -0.05"/>
     <geometry>
     <box size="0.15 0.1 0.1" />
     </geometry>
    </collision>

    <inertial>
     <origin rpy="0 0 0" xyz="0.05 0 -0.05"/>
      <mass value="0.03" />
      <inertia ixx="1.0" ixy="0.0" ixz="0.0"
                         iyy="1.0" iyz="0.0"
                                   izz="1.0" />
  </inertial>
   </link> 

  <joint name="joint6" type="revolute">
    <parent link="hind_leg_right"/>
    <child link="hind_leg_right2"/>
    <origin xyz="0 0 -0.3"/>
    <axis xyz="0 1 0"/>
    <limit lower="-0.3" upper="1.57" effort="0.5293" velocity="6.159937255" />
  </joint>
 <transmission name="trans6">
    <type>transmission_interface/SimpleTransmission</type>
    <joint name="joint6"> 
      <hardwareInterface>hardware_interface/EffortJointInterface</hardwareInterface>
    </joint>
    <actuator name="motor6">
       <hardwareInterface>hardware_interface/EffortJointInterface</hardwareInterface>
       <mechanismReduction>1</mechanismReduction>
    </actuator>
 </transmission>


<!--forth leg-->  
  <link name = "hind_leg_left">
   <visual>
    <geometry>
     <box size="0.1 0.1 0.3" />
    </geometry>
     <material name = "white"/>
     <origin rpy="0 0 0" xyz="0 0 -0.15"/>
    </visual>

    <collision>
     <origin rpy="0 0 0" xyz="0 0 -0.15"/>
     <geometry>
     <box size="0.1 0.1 0.3" />
     </geometry>
    </collision>

    <inertial>
     <origin rpy="0 0 0" xyz="0 0 -0.15"/>
      <mass value="0.03" />
      <inertia ixx="1.0" ixy="0.0" ixz="0.0"
                         iyy="1.0" iyz="0.0"
                                   izz="1.0" />
  </inertial>
   </link> 


  <joint name="joint7" type="revolute">
    <parent link="base_link"/>
    <child link="hind_leg_left"/>
    <origin xyz="-0.2 -0.2 0.5"/>
    <axis xyz="0 1 0"/>
    <limit lower="-1.57" upper="1.57" effort="0.5293" velocity="6.159937255" />
  </joint>
 <transmission name="trans7">
    <type>transmission_interface/SimpleTransmission</type>
    <joint name="joint7"> 
      <hardwareInterface>hardware_interface/EffortJointInterface</hardwareInterface>
    </joint>
    <actuator name="motor7">
       <hardwareInterface>hardware_interface/EffortJointInterface</hardwareInterface>
       <mechanismReduction>1</mechanismReduction>
    </actuator>
 </transmission>



  <link name = "hind_leg_left2">
   <visual>
    <geometry>
     <box size="0.15 0.1 0.1" />
    </geometry>
     <material name = "white"/>
     <origin rpy="0 0 0" xyz="0.05 0 -0.05"/>
    </visual>

    <collision>
     <origin rpy="0 0 0" xyz="0.05 0 -0.05"/>
     <geometry>
     <box size="0.15 0.1 0.1" />
     </geometry>
    </collision>

    <inertial>
     <origin rpy="0 0 0" xyz="0.05 0 -0.05"/>
      <mass value="0.03" />
      <inertia ixx="1.0" ixy="0.0" ixz="0.0"
                         iyy="1.0" iyz="0.0"
                                   izz="1.0" />
  </inertial>
   </link> 

  <joint name="joint8" type="revolute">
    <parent link="hind_leg_left"/>
    <child link="hind_leg_left2"/>
    <origin xyz="0 0 -0.3"/>
    <axis xyz="0 1 0"/>
    <limit lower="-0.3" upper="1.57" effort="0.5293" velocity="6.159937255" />
  </joint>
 <transmission name="trans8">
    <type>transmission_interface/SimpleTransmission</type>
    <joint name="joint8"> 
      <hardwareInterface>hardware_interface/EffortJointInterface</hardwareInterface>
    </joint>
    <actuator name="motor8">
       <hardwareInterface>hardware_interface/EffortJointInterface</hardwareInterface>
       <mechanismReduction>1</mechanismReduction>
    </actuator>
 </transmission>


<gazebo>
    <plugin name="gazebo_ros_control" filename="libgazebo_ros_control.so">
      <robotNamespace>/toydog</robotNamespace>
    </plugin>
</gazebo>

</robot>

